Workbook

Sheet Readme
B2: Sources:
A3: 1) | B3: Babecký ·et al. (2012)
B4: https://www.google.com/url?sa=t&rct=j&q=&esrc=s&source=web&cd=&cad=rja&uact=8&ved=2ahUKEwjckO7um4KMAxWuS0EAHWTSJdEQFnoECBkQAQ&url=https%3A%2F%2Fwww.ecb.europa.eu%2Fpub%2Fpdf%2Fscpops%2Fecb.op194.pt.pdf&usg=AOvVaw2GNoBiPv8DEd_oW1DP2aoP&opi=89978449
B5: EU27 Crises Database created with the help of the ESCB Heads of Research Group
B6: Approved in June 2012
B8: This dataset has been used for the accompanying ECB working paper:
B9: Banking, Debt, and Currency Crises:
B10: Early Warning Indicators for Developed Countries
B12: Jan Babecký a, Tomáš Havránek a,b, Jakub Matějů a,c,
B13: Marek Rusnák a,b, Kateřina Šmídková a,b, and Bořek Vašíček a
A15: 2) | B15: Laeven and Valencia (2020)
B16: Systemic Banking Crises Database II
A18: 3) | B18: FX
B19: Raw data: https://fred.stlouisfed.org/series/CCUSMA02IEQ618N
B20: CCUSMA02IEQ618N
B21: Currency Conversions: US Dollar Exchange Rate: Average of Daily Rates: National Currency: USD for Ireland, Euro, Quarterly, Not Seasonally Adjusted
B23: In C_Properties/C2.Properties.R code
B24: we detrend the FX (IE/US dollars)
B25: Results exported in
B26: C_Properties\1.Crisis_events\fx_filtered.xlsx
B27: We extend the currency crisis period reported in Babecky ·et al. (2012), by taking the period where the FX trend continued decreasing yoy
A29: 4) | B29: Baron and Dieckelmann (2022)
B30: file:///\\Filescluster\shared\MPS\WORD\MPFS%20DEPT\Farah\Alternative_Gap\New_Model\Ruenstler_and_Vlekke_2018\C_Robustness_Checks\1.Early_warnings\Bank_crisis\Raw_data\Baron_Dieckelmann_Panics_and_bank_failures_database.xlsx
B31: Link https://www.quantfinhistory.org/banking-crises-database
B32: Baron, M., & Dieckelmann, D. (2022). Historical Banking Crises: A New Database and a Reassessment of their Incidence and Severity. In: Leveraged: The New Economics of Debt and Financial Fragility. University of Chicago Press, forthcoming.
B33: The Historical Banking Crises Database
B34: 42 countries, 1870-2019
B35: Banking crisis characteristics
B36: Banking panics and bank failures, 1870-2016
B38: Notes:
B39: Crisis_Babecky | D39: All the sources excluding Bank Eq. 30% decline.
B40: Crisis_Babecky_Baron | D40: All the sources excluding Bank Eq. 30% decline.
B41: Labels: just for the graphs produced in C2.Properties.R
B44: Farah Mugrabi

Sheet Crisis
A1: Date | B1: Crisis_Babecky | C1: Crisis_Babecky_Baron | D1: Reference | E1: Label
A2: 28491 | B2: =Crisis_construction!F3 -> 0 | C2: =Crisis_construction!G3 -> 0 | D2: =+Crisis_construction!I3 -> 0
A3: 28581 | B3: =Crisis_construction!F4 -> 0 | C3: =Crisis_construction!G4 -> 0 | D3: =+Crisis_construction!I4 -> 0
A4: 28672 | B4: =Crisis_construction!F5 -> 0 | C4: =Crisis_construction!G5 -> 0 | D4: =+Crisis_construction!I5 -> 0
A5: 28764 | B5: =Crisis_construction!F6 -> 0 | C5: =Crisis_construction!G6 -> 0 | D5: =+Crisis_construction!I6 -> 0
A6: 28856 | B6: =Crisis_construction!F7 -> 0 | C6: =Crisis_construction!G7 -> 0 | D6: =+Crisis_construction!I7 -> 0
A7: 28946 | B7: =Crisis_construction!F8 -> 0 | C7: =Crisis_construction!G8 -> 0 | D7: =+Crisis_construction!I8 -> 0
A8: 29037 | B8: =Crisis_construction!F9 -> 0 | C8: =Crisis_construction!G9 -> 0 | D8: =+Crisis_construction!I9 -> 0
A9: 29129 | B9: =Crisis_construction!F10 -> 0 | C9: =Crisis_construction!G10 -> 0 | D9: =+Crisis_construction!I10 -> 0
A10: 29221 | B10: =Crisis_construction!F11 -> 0 | C10: =Crisis_construction!G11 -> 0 | D10: =+Crisis_construction!I11 -> 0
A11: 29312 | B11: =Crisis_construction!F12 -> 0 | C11: =Crisis_construction!G12 -> 0 | D11: =+Crisis_construction!I12 -> 0
A12: 29403 | B12: =Crisis_construction!F13 -> 0 | C12: =Crisis_construction!G13 -> 0 | D12: =+Crisis_construction!I13 -> 0
A13: 29495 | B13: =Crisis_construction!F14 -> 0 | C13: =Crisis_construction!G14 -> 0 | D13: =+Crisis_construction!I14 -> 0
... A29: 30956 | B29: =Crisis_construction!F30 -> 0 | C29: =Crisis_construction!G30 -> 0 | D29: =+Crisis_construction!I30 -> 0
A30: 31048 | B30: =Crisis_construction!F31 -> 1 | C30: =Crisis_construction!G31 -> 1 | D30: =+Crisis_construction!I31 -> Babecky ·et al. (2012) - Currency crisis. | E30: 1
A31: 31138 | B31: =Crisis_construction!F32 -> 0 | C31: =Crisis_construction!G32 -> 0 | D31: =+Crisis_construction!I32 -> 0
A32: 31229 | B32: =Crisis_construction!F33 -> 1 | C32: =Crisis_construction!G33 -> 1 | D32: =+Crisis_construction!I33 -> FX (US/IE) substantial decline - Currency crisis. | E32: 0.9
A33: 31321 | B33: =Crisis_construction!F34 -> 1 | C33: =Crisis_construction!G34 -> 1 | D33: =+Crisis_construction!I34 -> 0
A34: 31413 | B34: =Crisis_construction!F35 -> 1 | C34: =Crisis_construction!G35 -> 1 | D34: =+Crisis_construction!I35 -> 0
A35: 31503 | B35: =Crisis_construction!F36 -> 1 | C35: =Crisis_construction!G36 -> 1 | D35: =+Crisis_construction!I36 -> 0
A36: 31594 | B36: =Crisis_construction!F37 -> 1 | C36: =Crisis_construction!G37 -> 1 | D36: =+Crisis_construction!I37 -> 0
A37: 31686 | B37: =Crisis_construction!F38 -> 1 | C37: =Crisis_construction!G38 -> 1 | D37: =+Crisis_construction!I38 -> 0
A38: 31778 | B38: =Crisis_construction!F39 -> 1 | C38: =Crisis_construction!G39 -> 1 | D38: =+Crisis_construction!I39 -> 0
A39: 31868 | B39: =Crisis_construction!F40 -> 1 | C39: =Crisis_construction!G40 -> 1 | D39: =+Crisis_construction!I40 -> 0
A40: 31959 | B40: =Crisis_construction!F41 -> 1 | C40: =Crisis_construction!G41 -> 1 | D40: =+Crisis_construction!I41 -> 0
A41: 32051 | B41: =Crisis_construction!F42 -> 1 | C41: =Crisis_construction!G42 -> 1 | D41: =+Crisis_construction!I42 -> 0
A42: 32143 | B42: =Crisis_construction!F43 -> 1 | C42: =Crisis_construction!G43 -> 1 | D42: =+Crisis_construction!I43 -> 0
A43: 32234 | B43: =Crisis_construction!F44 -> 1 | C43: =Crisis_construction!G44 -> 1 | D43: =+Crisis_construction!I44 -> 0
A44: 32325 | B44: =Crisis_construction!F45 -> 0 | C44: =Crisis_construction!G45 -> 0 | D44: =+Crisis_construction!I45 -> 0
... A49: 32782 | B49: =Crisis_construction!F50 -> 0 | C49: =Crisis_construction!G50 -> 0 | D49: =+Crisis_construction!I50 -> 0
A50: 32874 | B50: =Crisis_construction!F51 -> 0 | C50: =Crisis_construction!G51 -> 1 | D50: =+Crisis_construction!I51 -> Baron and Dieckelmann (2022) -Bank Eq. 30% decline. | E50: 0.8
A51: 32964 | B51: =Crisis_construction!F52 -> 0 | C51: =Crisis_construction!G52 -> 1 | D51: =+Crisis_construction!I52 -> 0
A52: 33055 | B52: =Crisis_construction!F53 -> 0 | C52: =Crisis_construction!G53 -> 1 | D52: =+Crisis_construction!I53 -> 0
A53: 33147 | B53: =Crisis_construction!F54 -> 0 | C53: =Crisis_construction!G54 -> 1 | D53: =+Crisis_construction!I54 -> 0
A54: 33239 | B54: =Crisis_construction!F55 -> 0 | C54: =Crisis_construction!G55 -> 0 | D54: =+Crisis_construction!I55 -> 0
A55: 33329 | B55: =Crisis_construction!F56 -> 0 | C55: =Crisis_construction!G56 -> 0 | D55: =+Crisis_construction!I56 -> 0
A56: 33420 | B56: =Crisis_construction!F57 -> 0 | C56: =Crisis_construction!G57 -> 0 | D56: =+Crisis_construction!I57 -> 0
A57: 33512 | B57: =Crisis_construction!F58 -> 0 | C57: =Crisis_construction!G58 -> 0 | D57: =+Crisis_construction!I58 -> 0
A58: 33604 | B58: =Crisis_construction!F59 -> 0 | C58: =Crisis_construction!G59 -> 0 | D58: =+Crisis_construction!I59 -> 0
A59: 33695 | B59: =Crisis_construction!F60 -> 0 | C59: =Crisis_construction!G60 -> 0 | D59: =+Crisis_construction!I60 -> 0
...

Sheet Crisis_construction
B1: Raw_sources
A2: Date | B2: Babecky ·et al. (2012) | C2: Laeven and Valencia (2020) | D2: FX | E2: Baron and Dieckelmann (2022) | F2: Crisis_Babecky | G2: Crisis_Babecky_Baron | I2: Reference
A3: 28491 | B3: ='Babecky ·et al. (2012)'!B34 -> 0 | D3: =FX!F2 -> 0 | E3: 0 | F3: =+IF(SUM(B3:D3)=0,0,1) -> 0 | G3: =+IF(SUM(B3:E3)=0,0,1) -> 0
A4: 28581 | B4: ='Babecky ·et al. (2012)'!B35 -> 0 | D4: =FX!F3 -> 0 | E4: 0 | F4: =+IF(SUM(B4:D4)=0,0,1) -> 0 | G4: =+IF(SUM(B4:E4)=0,0,1) -> 0
A5: 28672 | B5: ='Babecky ·et al. (2012)'!B36 -> 0 | D5: =FX!F4 -> 0 | E5: 0 | F5: =+IF(SUM(B5:D5)=0,0,1) -> 0 | G5: =+IF(SUM(B5:E5)=0,0,1) -> 0
A6: 28764 | B6: ='Babecky ·et al. (2012)'!B37 -> 0 | D6: =FX!F5 -> 0 | E6: 0 | F6: =+IF(SUM(B6:D6)=0,0,1) -> 0 | G6: =+IF(SUM(B6:E6)=0,0,1) -> 0
A7: 28856 | B7: ='Babecky ·et al. (2012)'!B38 -> 0 | D7: =FX!F6 -> 0 | E7: 0 | F7: =+IF(SUM(B7:D7)=0,0,1) -> 0 | G7: =+IF(SUM(B7:E7)=0,0,1) -> 0
A8: 28946 | B8: ='Babecky ·et al. (2012)'!B39 -> 0 | D8: =FX!F7 -> 0 | E8: 0 | F8: =+IF(SUM(B8:D8)=0,0,1) -> 0 | G8: =+IF(SUM(B8:E8)=0,0,1) -> 0
A9: 29037 | B9: ='Babecky ·et al. (2012)'!B40 -> 0 | D9: =FX!F8 -> 0 | E9: 0 | F9: =+IF(SUM(B9:D9)=0,0,1) -> 0 | G9: =+IF(SUM(B9:E9)=0,0,1) -> 0
A10: 29129 | B10: ='Babecky ·et al. (2012)'!B41 -> 0 | D10: =FX!F9 -> 0 | E10: 0 | F10: =+IF(SUM(B10:D10)=0,0,1) -> 0 | G10: =+IF(SUM(B10:E10)=0,0,1) -> 0
A11: 29221 | B11: ='Babecky ·et al. (2012)'!B42 -> 0 | D11: =FX!F10 -> 0 | E11: 0 | F11: =+IF(SUM(B11:D11)=0,0,1) -> 0 | G11: =+IF(SUM(B11:E11)=0,0,1) -> 0
A12: 29312 | B12: ='Babecky ·et al. (2012)'!B43 -> 0 | D12: =FX!F11 -> 0 | E12: 0 | F12: =+IF(SUM(B12:D12)=0,0,1) -> 0 | G12: =+IF(SUM(B12:E12)=0,0,1) -> 0
A13: 29403 | B13: ='Babecky ·et al. (2012)'!B44 -> 0 | D13: =FX!F12 -> 0 | E13: 0 | F13: =+IF(SUM(B13:D13)=0,0,1) -> 0 | G13: =+IF(SUM(B13:E13)=0,0,1) -> 0
A14: 29495 | B14: ='Babecky ·et al. (2012)'!B45 -> 0 | D14: =FX!F13 -> 0 | E14: 0 | F14: =+IF(SUM(B14:D14)=0,0,1) -> 0 | G14: =+IF(SUM(B14:E14)=0,0,1) -> 0
... A30: 30956 | B30: ='Babecky ·et al. (2012)'!B61 -> 0 | D30: =FX!F29 -> 0 | E30: 0 | F30: =+IF(SUM(B30:D30)=0,0,1) -> 0 | G30: =+IF(SUM(B30:E30)=0,0,1) -> 0
A31: 31048 | B31: ='Babecky ·et al. (2012)'!B62 -> 1 | D31: =FX!F30 -> 0 | E31: 0 | F31: =+IF(SUM(B31:D31)=0,0,1) -> 1 | G31: =+IF(SUM(B31:E31)=0,0,1) -> 1 | I31: Babecky ·et al. (2012) - Currency crisis.
A32: 31138 | B32: ='Babecky ·et al. (2012)'!B63 -> 0 | D32: =FX!F31 -> 0 | E32: 0 | F32: =+IF(SUM(B32:D32)=0,0,1) -> 0 | G32: =+IF(SUM(B32:E32)=0,0,1) -> 0
A33: 31229 | B33: ='Babecky ·et al. (2012)'!B64 -> 0 | D33: =FX!F32 -> 1 | E33: 0 | F33: =+IF(SUM(B33:D33)=0,0,1) -> 1 | G33: =+IF(SUM(B33:E33)=0,0,1) -> 1 | I33: FX (US/IE) substantial decline - Currency crisis.
A34: 31321 | B34: ='Babecky ·et al. (2012)'!B65 -> 0 | D34: =FX!F33 -> 1 | E34: 0 | F34: =+IF(SUM(B34:D34)=0,0,1) -> 1 | G34: =+IF(SUM(B34:E34)=0,0,1) -> 1
A35: 31413 | B35: ='Babecky ·et al. (2012)'!B66 -> 0 | D35: =FX!F34 -> 1 | E35: 0 | F35: =+IF(SUM(B35:D35)=0,0,1) -> 1 | G35: =+IF(SUM(B35:E35)=0,0,1) -> 1
A36: 31503 | B36: ='Babecky ·et al. (2012)'!B67 -> 0 | D36: =FX!F35 -> 1 | E36: 0 | F36: =+IF(SUM(B36:D36)=0,0,1) -> 1 | G36: =+IF(SUM(B36:E36)=0,0,1) -> 1
A37: 31594 | B37: ='Babecky ·et al. (2012)'!B68 -> 0 | D37: =FX!F36 -> 1 | E37: 0 | F37: =+IF(SUM(B37:D37)=0,0,1) -> 1 | G37: =+IF(SUM(B37:E37)=0,0,1) -> 1
A38: 31686 | B38: ='Babecky ·et al. (2012)'!B69 -> 0 | D38: =FX!F37 -> 1 | E38: 0 | F38: =+IF(SUM(B38:D38)=0,0,1) -> 1 | G38: =+IF(SUM(B38:E38)=0,0,1) -> 1
A39: 31778 | B39: ='Babecky ·et al. (2012)'!B70 -> 0 | D39: =FX!F38 -> 1 | E39: 0 | F39: =+IF(SUM(B39:D39)=0,0,1) -> 1 | G39: =+IF(SUM(B39:E39)=0,0,1) -> 1
A40: 31868 | B40: ='Babecky ·et al. (2012)'!B71 -> 0 | D40: =FX!F39 -> 1 | E40: 0 | F40: =+IF(SUM(B40:D40)=0,0,1) -> 1 | G40: =+IF(SUM(B40:E40)=0,0,1) -> 1
A41: 31959 | B41: ='Babecky ·et al. (2012)'!B72 -> 0 | D41: =FX!F40 -> 1 | E41: 0 | F41: =+IF(SUM(B41:D41)=0,0,1) -> 1 | G41: =+IF(SUM(B41:E41)=0,0,1) -> 1
A42: 32051 | B42: ='Babecky ·et al. (2012)'!B73 -> 0 | D42: =FX!F41 -> 1 | E42: 0 | F42: =+IF(SUM(B42:D42)=0,0,1) -> 1 | G42: =+IF(SUM(B42:E42)=0,0,1) -> 1
A43: 32143 | B43: ='Babecky ·et al. (2012)'!B74 -> 0 | D43: =FX!F42 -> 1 | E43: 0 | F43: =+IF(SUM(B43:D43)=0,0,1) -> 1 | G43: =+IF(SUM(B43:E43)=0,0,1) -> 1
A44: 32234 | B44: ='Babecky ·et al. (2012)'!B75 -> 0 | D44: =FX!F43 -> 1 | E44: 0 | F44: =+IF(SUM(B44:D44)=0,0,1) -> 1 | G44: =+IF(SUM(B44:E44)=0,0,1) -> 1
A45: 32325 | B45: ='Babecky ·et al. (2012)'!B76 -> 0 | D45: =FX!F44 -> 0 | E45: 0 | F45: =+IF(SUM(B45:D45)=0,0,1) -> 0 | G45: =+IF(SUM(B45:E45)=0,0,1) -> 0
... A50: 32782 | B50: ='Babecky ·et al. (2012)'!B81 -> 0 | D50: =FX!F49 -> 0 | E50: 0 | F50: =+IF(SUM(B50:D50)=0,0,1) -> 0 | G50: =+IF(SUM(B50:E50)=0,0,1) -> 0
A51: 32874 | B51: ='Babecky ·et al. (2012)'!B82 -> 0 | D51: =FX!F50 -> 0 | E51: 1 | F51: =+IF(SUM(B51:D51)=0,0,1) -> 0 | G51: =+IF(SUM(B51:E51)=0,0,1) -> 1 | I51: Baron and Dieckelmann (2022) -Bank Eq. 30% decline.
A52: 32964 | B52: ='Babecky ·et al. (2012)'!B83 -> 0 | D52: =FX!F51 -> 0 | E52: 1 | F52: =+IF(SUM(B52:D52)=0,0,1) -> 0 | G52: =+IF(SUM(B52:E52)=0,0,1) -> 1
A53: 33055 | B53: ='Babecky ·et al. (2012)'!B84 -> 0 | D53: =FX!F52 -> 0 | E53: 1 | F53: =+IF(SUM(B53:D53)=0,0,1) -> 0 | G53: =+IF(SUM(B53:E53)=0,0,1) -> 1
A54: 33147 | B54: ='Babecky ·et al. (2012)'!B85 -> 0 | D54: =FX!F53 -> 0 | E54: 1 | F54: =+IF(SUM(B54:D54)=0,0,1) -> 0 | G54: =+IF(SUM(B54:E54)=0,0,1) -> 1
A55: 33239 | B55: ='Babecky ·et al. (2012)'!B86 -> 0 | D55: =FX!F54 -> 0 | E55: 0 | F55: =+IF(SUM(B55:D55)=0,0,1) -> 0 | G55: =+IF(SUM(B55:E55)=0,0,1) -> 0
A56: 33329 | B56: ='Babecky ·et al. (2012)'!B87 -> 0 | D56: =FX!F55 -> 0 | E56: 0 | F56: =+IF(SUM(B56:D56)=0,0,1) -> 0 | G56: =+IF(SUM(B56:E56)=0,0,1) -> 0
A57: 33420 | B57: ='Babecky ·et al. (2012)'!B88 -> 0 | D57: =FX!F56 -> 0 | E57: 0 | F57: =+IF(SUM(B57:D57)=0,0,1) -> 0 | G57: =+IF(SUM(B57:E57)=0,0,1) -> 0
A58: 33512 | B58: ='Babecky ·et al. (2012)'!B89 -> 0 | D58: =FX!F57 -> 0 | E58: 0 | F58: =+IF(SUM(B58:D58)=0,0,1) -> 0 | G58: =+IF(SUM(B58:E58)=0,0,1) -> 0
A59: 33604 | B59: ='Babecky ·et al. (2012)'!B90 -> 0 | D59: =FX!F58 -> 0 | E59: 0 | F59: =+IF(SUM(B59:D59)=0,0,1) -> 0 | G59: =+IF(SUM(B59:E59)=0,0,1) -> 0
...

Sheet FX
A1: Date | B1: FX | C1: hp_trend_FX | D1: hp_cycle_FX | E1: FX_yoy | F1: Dummy_currency_crisis | G1: Babecky ·et al. (2012
A2: 28491 | B2: 0.65827454 | C2: 0.57077996 | D2: 0.087494587
A3: 28581 | B3: 0.69183795 | C3: 0.58566262 | D3: 0.10617533
A4: 28672 | B4: 0.6578513 | C4: 0.60059997 | D4: 0.057251333
A5: 28764 | B5: 0.64024426 | C5: 0.61571304 | D5: 0.024531225
A6: 28856 | B6: 0.63004403 | C6: 0.63115867 | D6: -0.0011146312 | E6: =B6/B2-1 -> -0.042885617
A7: 28946 | B7: 0.63419185 | C7: 0.647109 | D7: -0.012917159 | E7: =B7/B3-1 -> -0.083323137
A8: 29037 | B8: 0.61256397 | C8: 0.66373552 | D8: -0.051171542 | E8: =B8/B4-1 -> -0.068841279
A9: 29129 | B9: 0.6048609 | C9: 0.68120159 | D9: -0.076340691 | E9: =B9/B5-1 -> -0.055265419
A10: 29221 | B10: 0.60837384 | C10: 0.69963862 | D10: -0.091264787 | E10: =B10/B6-1 -> -0.034394733
A11: 29312 | B11: 0.61641551 | C11: 0.71913032 | D11: -0.10271481 | E11: =B11/B7-1 -> -0.028029899
A12: 29403 | B12: 0.59838523 | C12: 0.73970333 | D12: -0.1413181 | E12: =B12/B8-1 -> -0.023146549
A13: 29495 | B13: 0.64862454 | C13: 0.7613201 | D13: -0.11269557 | E13: =B13/B9-1 -> 0.072353229
A14: 29587 | B14: 0.71676715 | C14: 0.78385478 | D14: -0.067087632 | E14: =B14/B10-1 -> 0.17816892
A15: 29677 | B15: 0.79062358 | C15: 0.80711105 | D15: -0.01648747 | E15: =B15/B11-1 -> 0.28261467
A16: 29768 | B16: 0.84687297 | C16: 0.83085068 | D16: 0.016022295 | E16: =B16/B12-1 -> 0.41526383
A17: 29860 | B17: 0.80310933 | C17: 0.85482514 | D17: -0.051715801 | E17: =B17/B13-1 -> 0.23817292
... A29: 30956 | B29: 1.2480679 | C29: 1.0564764 | D29: 0.19159149 | E29: =B29/B25-1 -> 0.13963285
A30: 31048 | B30: 1.3266647 | C30: 1.0574893 | D30: 0.26917536 | E30: =B30/B26-1 -> 0.191191 | G30: 1 | H30: Babecky ·et al. (2012), starting point of the currency crisis. We extend the period for what the FX fall after this quarter
A31: 31138 | B31: 1.2520887 | C31: 1.05538 | D31: 0.19670875 | E31: =B31/B27-1 -> 0.11562394
A32: 31229 | B32: 1.1616834 | C32: 1.0503725 | D32: 0.11131084 | E32: =B32/B28-1 -> -0.034168485 | F32: 1
A33: 31321 | B33: 1.0628977 | C33: 1.0428141 | D33: 0.020083601 | E33: =B33/B29-1 -> -0.14836544 | F33: 1
A34: 31413 | B34: 0.98404701 | C34: 1.0331215 | D34: -0.049074485 | E34: =B34/B30-1 -> -0.25825491 | F34: 1
A35: 31503 | B35: 0.93867504 | C35: 1.0217238 | D35: -0.0830488 | E35: =B35/B31-1 -> -0.25031268 | F35: 1
A36: 31594 | B36: 0.93435793 | C36: 1.0090197 | D36: -0.074661818 | E36: =B36/B32-1 -> -0.19568623 | F36: 1
A37: 31686 | B37: 0.93490815 | C37: 0.99535589 | D37: -0.060447746 | E37: =B37/B33-1 -> -0.12041572 | F37: 1
A38: 31778 | B38: 0.87362212 | C38: 0.98103229 | D38: -0.10741017 | E38: =B38/B34-1 -> -0.11221505 | F38: 1
A39: 31868 | B39: 0.85664996 | C39: 0.96631116 | D39: -0.10966121 | E39: =B39/B35-1 -> -0.087383894 | F39: 1
A40: 31959 | B40: 0.87027848 | C40: 0.95138761 | D40: -0.081109133 | E40: =B40/B36-1 -> -0.068581265 | F40: 1
A41: 32051 | B41: 0.81500255 | C41: 0.93638819 | D41: -0.12138565 | E41: =B41/B37-1 -> -0.12825388 | F41: 1
A42: 32143 | B42: 0.80035824 | C42: 0.89710243 | D42: -0.096744192 | E42: =B42/B38-1 -> -0.083862216 | F42: 1
A43: 32234 | B43: 0.81017754 | C43: 0.86550676 | D43: -0.055329215 | E43: =B43/B39-1 -> -0.054249012 | F43: 1
A44: 32325 | B44: 0.88301818 | C44: 0.85362823 | D44: 0.029389958 | E44: =B44/B40-1 -> 0.014638654
A45: 32417 | B45: 0.84285214 | C45: 0.83673136 | D45: 0.0061207781 | E45: =B45/B41-1 -> 0.034171167
A46: 32509 | B46: 0.87967454 | C46: 0.83074809 | D46: 0.048926448 | E46: =B46/B42-1 -> 0.099101005
A47: 32599 | B47: 0.91912107 | C47: 0.83497152 | D47: 0.084149547 | E47: =B47/B43-1 -> 0.13446871
A48: 32690 | B48: 0.91548115 | C48: 0.83949807 | D48: 0.075983084 | E48: =B48/B44-1 -> 0.036763649
A49: 32782 | B49: 0.86972826 | C49: 0.83563728 | D49: 0.034090975 | E49: =B49/B45-1 -> 0.031887115
A50: 32874 | B50: 0.80903478 | C50: 0.82113894 | D50: -0.012104156 | E50: =B50/B46-1 -> -0.080302156
A51: 32964 | B51: 0.79506766 | C51: 0.80647664 | D51: -0.011408975 | E51: =B51/B47-1 -> -0.13496961
...

Sheet Babecky ·et al. (2012)
A1: TYPE OF EVENT | B1: BANKING CRISES | C1: CURRENCY (BOP) CRISES | D1: DEBT CRISES | E1: all
A2: 1970 - I. | B2: 0 | C2: 0 | D2: 0 | E2: =IF(SUM(B2:D2)=0,0,1) -> 0
A3: 1970 - II. | B3: 0 | C3: 0 | D3: 0 | E3: =IF(SUM(B3:D3)=0,0,1) -> 0
A4: 1970 - III. | B4: 0 | C4: 0 | D4: 0 | E4: =IF(SUM(B4:D4)=0,0,1) -> 0
A5: 1970 - IV. | B5: 0 | C5: 0 | D5: 0 | E5: =IF(SUM(B5:D5)=0,0,1) -> 0
A6: 1971 - I. | B6: 0 | C6: 0 | D6: 0 | E6: =IF(SUM(B6:D6)=0,0,1) -> 0
A7: 1971 - II. | B7: 0 | C7: 0 | D7: 0 | E7: =IF(SUM(B7:D7)=0,0,1) -> 0
A8: 1971 - III. | B8: 0 | C8: 0 | D8: 0 | E8: =IF(SUM(B8:D8)=0,0,1) -> 0
A9: 1971 - IV. | B9: 0 | C9: 0 | D9: 0 | E9: =IF(SUM(B9:D9)=0,0,1) -> 0
A10: 1972 - I. | B10: 0 | C10: 0 | D10: 0 | E10: =IF(SUM(B10:D10)=0,0,1) -> 0
A11: 1972 - II. | B11: 0 | C11: 0 | D11: 0 | E11: =IF(SUM(B11:D11)=0,0,1) -> 0
A12: 1972 - III. | B12: 0 | C12: 0 | D12: 0 | E12: =IF(SUM(B12:D12)=0,0,1) -> 0
A13: 1972 - IV. | B13: 0 | C13: 0 | D13: 0 | E13: =IF(SUM(B13:D13)=0,0,1) -> 0
... A165: 2010 - IV. | B165: 1 | C165: 0 | D165: 1 | E165: =IF(SUM(B165:D165)=0,0,1) -> 1

Sheet Laeven and Valencia (2020)
A1: Country | B1: Start | C1: End | D1: Output loss 1/ | E1: Fiscal Costs 2/ (% of GDP) | F1: Fiscal Costs, net 2/ (% of GDP) | G1: Fiscal cost (% of financial sector assets) | H1: Peak liquidity 3/ | I1: Liquidity support 3/ | J1: Peak NPLs 4/ | K1: Increase in public debt 5/
A2: Albania | B2: 1994 | C2: 1994 | D2: … | E2: ... | F2: ... | G2: ... | H2: 7.615962 | I2: ... | J2: 26.8 | K2: ...
A3: Algeria | B3: 1990 | C3: 1994 7/ | D3: 41.392253 | E3: ... | F3: ... | G3: ... | H3: 37.56032 | I3: 29.85246 | J3: 30 | K3: 19.10056
A4: Argentina | B4: 1980 | C4: 1982 6/ | D4: 58.171235 | E4: 55.1 | F4: 55.1 | G4: 213.89751 | H4: 64.64586 | I4: 62.21225 | J4: 9 | K4: 33.14739
A5: Argentina | B5: 1989 | C5: 1991 | D5: 12.629947 | E5: 6 | F5: 6 | G5: 21.606049 | H5: 151.5721 | I5: 135.665 | J5: 27 | K5: -21.29261
A6: Argentina 8/ | B6: 1995 | C6: 1995 | D6: 0 | E6: 2 | F6: 2 | G6: 8.550663 | H6: 71.3528 | I6: 62.99766 | J6: 17 | K6: 8.69467
A7: Argentina | B7: 2001 | C7: 2003 | D7: 70.974199 | E7: 9.6 | F7: 9.5846645 | G7: 28.094822 | H7: 22.85839 | I7: 22.64661 | J7: 20.1 | K7: 81.88721
A8: Armenia 4/ | B8: 1994 | C8: 1994 6/ | D8: … | E8: ... | F8: ... | G8: ... | H8: 41.37691 | I8: 22.99402 | J8: ... | K8: ...
A9: Austria | B9: 2008 | C9: 2012 7/ | D9: 19.215918 | E9: =+'[1]Additional Details-Bk Crises'!F47*100 -> 5.15 | F9: 1.64 | G9: 1.6435314 | H9: 10.02 | I9: 6.41 | J9: =+'[1]Additional Details-Bk Crises'!F45*100 -> 4.1 | K9: 19.8
A10: Azerbaijan | B10: 1995 | C10: 1995 6/ | D10: ... | E10: ... | F10: ... | G10: ... | H10: 127.5802 | I10: 84.46377 | J10: ... | K10: 0.89603
A11: Bangladesh | B11: 1987 | C11: 1987 | D11: 0 | E11: ... | F11: ... | G11: ... | H11: 25.96208 | I11: 2.82342 | J11: 20 | K11: 3.4759
A12: Belarus | B12: 1995 | C12: 1995 | D12: ... | E12: ... | F12: ... | G12: ... | H12: 35.7598 | I12: ... | J12: ... | K12: -16.45655
A13: Belgium | B13: 2008 | C13: 2012 7/ | D13: 15.732718 | E13: =+'[1]Additional Details-Bk Crises'!G47*100 -> 6.15 | F13: 0.46 | G13: 1.6283828 | H13: 13.69 | I13: 9.67 | J13: =100*'[1]Additional Details-Bk Crises'!G45 -> 4.24 | K13: 22.2
A14: Benin | B14: 1988 | C14: 1992 7/ | D14: 14.917588 | E14: 17 | F14: ... | G14: 64.320847 | H14: 99.64091 | I14: 48.62441 | J14: 80 | K14: 5.67801
A15: Bolivia | B15: 1986 | C15: 1986 | D15: 49.191735 | E15: ... | F15: ... | G15: ... | H15: 57.52545 | I15: 25.92482 | J15: 30 | K15: -107.2825
A16: Bolivia | B16: 1994 | C16: 1994 | D16: 0 | E16: 6 | F16: 2.6533333 | G16: 15.193719 | H16: 31.92642 | I16: 12.89265 | J16: 6.2 | K16: -19.21072
A17: Bosnia and Herzegovina | B17: 1992 | C17: 1996 7/ | D17: ... | E17: ... | F17: ... | G17: ... | H17: ... | I17: ... | J17: ... | K17: ...
A18: Brazil 8/ | B18: 1990 | C18: 1994 7/ | D18: 62.295604 | E18: 0 | F18: 0 | G18: 0 | H18: 11.26261 | I18: 10.71347 | J18: ... | K18: -22.64
A19: Brazil | B19: 1994 | C19: 1998 | D19: 0 | E19: 13.2 | F19: 10.2 | G19: 28.596188 | H19: 20.11846 | I19: 17.61162 | J19: 16 | K19: -33.77793
A20: Bulgaria | B20: 1996 | C20: 1997 | D20: 59.510493 | E20: 14 | F20: 13.9 | G20: 21.370783 | H20: 17.30571 | I20: 9.93675 | J20: 75 | K20: -30.07973
A21: Burkina Faso | B21: 1990 | C21: 1994 | D21: ... | E21: ... | F21: ... | G21: ... | H21: 9.3824 | I21: 4.51769 | J21: 16 | K21: 8.92432
A22: Burundi | B22: 1994 | C22: 1998 7/ | D22: 121.192 | E22: ... | F22: ... | G22: ... | H22: 23.44168 | I22: 18.25261 | J22: 25 | K22: 10.85286
A23: Cameroon | B23: 1987 | C23: 1991 7/ | D23: 105.52664 | E23: ... | F23: ... | G23: ... | H23: 59.10603 | I23: 40.85175 | J23: 65 | K23: 17.96692
A24: Cameroon | B24: 1995 | C24: 1997 | D24: 8.0982519 | E24: ... | F24: ... | G24: ... | H24: 12.31134 | I24: 6.16095 | J24: 30 | K24: -1.06627
A25: Cape Verde | B25: 1993 | C25: 1993 | D25: 0 | E25: ... | F25: ... | G25: ... | H25: 3.967447 | I25: ... | J25: 30 | K25: 18.15971
A26: Central African Rep | B26: 1976 | C26: 1976 | D26: 0 | E26: ... | F26: ... | G26: ... | H26: 90.84164 | I26: 10.4593 | J26: ... | K26: -4.77751
A27: Central African Rep | B27: 1995 | C27: 1996 | D27: 8.9569594 | E27: ... | F27: ... | G27: ... | H27: 24.83221 | I27: 20.94306 | J27: 40 | K27: -16.26852
A28: Chad | B28: 1983 | C28: 1983 | D28: 0 | E28: ... | F28: ... | G28: ... | H28: 199.305 | I28: 41.31468 | J28: ... | K28: -7.16883
A29: Chad | B29: 1992 | C29: 1996 7/ | D29: 0 | E29: ... | F29: ... | G29: ... | H29: 120.8667 | I29: 41.38313 | J29: 35 | K29: 27.0806
A30: Chile | B30: 1976 | C30: 1976 | D30: 19.89855 | E30: ... | F30: ... | G30: ... | H30: 32.20038 | I30: 23.63696 | J30: ... | K30: -69.52382
A31: Chile | B31: 1981 | C31: 1985 7/ | D31: 8.6097452 | E31: 42.9 | F31: 16.8 | G31: 134.31433 | H31: 61.22512 | I31: 52.6979 | J31: 35.6 | K31: 87.8976
A32: China, Mainland | B32: 1998 | C32: 1998 | D32: 19.398311 | E32: 18 | F32: ... | G32: 19.53125 | H32: 62.01519 | I32: 7.19216 | J32: 20 | K32: 11.15775
A33: Colombia | B33: 1982 | C33: 1982 | D33: 46.959534 | E33: 5 | F33: 5 | G33: 16.496206 | H33: 21.06028 | I33: 7.73772 | J33: 4.1 | K33: 16.57043
A34: Colombia | B34: 1998 | C34: 2000 | D34: 43.398161 | E34: 6.3 | F34: 2.54 | G34: 15.897047 | H34: 5.073536 | I34: 4.29109 | J34: 14 | K34: 15.40799
A35: Congo, Dem Rep | B35: 1983 | C35: 1983 | D35: 1.3754204 | E35: ... | F35: ... | G35: ... | H35: 19.95647 | I35: 18.91813 | J35: ... | K35: 39.45382
A36: Congo, Dem Rep | B36: 1991 | C36: 1994 7/ | D36: 129.54675 | E36: ... | F36: ... | G36: ... | H36: 44.69853 | I36: 30.17046 | J36: ... | K36: 42.1884
A37: Congo, Dem Rep | B37: 1994 | C37: 1998 7/ | D37: 78.991939 | E37: ... | F37: ... | G37: ... | H37: 77.25292 | I37: 77.11886 | J37: 75 | K37: 39.25775
A38: Congo, Rep | B38: 1992 | C38: 1994 | D38: 47.359838 | E38: ... | F38: ... | G38: ... | H38: 30.73201 | I38: 16.58411 | J38: ... | K38: 103.4631
A39: Costa Rica | B39: 1987 | C39: 1991 | D39: 0 | E39: ... | F39: ... | G39: ... | H39: 20.17417 | I39: 6.09581 | J39: ... | K39: -27.54878
A40: Costa Rica | B40: 1994 | C40: 1995 | D40: 0 | E40: ... | F40: ... | G40: ... | H40: 15.1952 | I40: 6.34947 | J40: 32 | K40: 4.75884
...

Sheet Baron and Dieckelmann (2022)
A1: Country | B1: BVX Year | C1: Bank Eq. 30% decline | D1: Narrative Crisis | E1: Panic | F1: Panic month | G1: Widespread bank failures | H1: PANIC BANKING CRISIS | I1: BANK EQUITY CRISIS | J1: BVX list: UNION OF TWO TYPES | K1: Bank failures | L1: Sources Bank failures | M1: Documentation of Panic indicator & Panic month | N1: Other historical background & sources
A2: Argentina | B2: 1885 | C2: 0 | D2: 1 | E2: 0 | G2: 0 | H2: 0 | I2: 0 | J2: 0 | M2: Bordo and Eichengreen (1999) consider this a currency crisis but not a banking crisis. Reinhart & Rogoff (2014) no longer consider this a banking crisis in their 2014 update. There is no evidence of bank runs. | N2: Della Paolera & Taylor (2001, pp. 37-64) report that by 1884 banks suspended convertibility of notes for specie. A short period of currency volatility ensued that did not seem to have had substantial real effects.
A3: Argentina | B3: 1891 | C3: 1 | D3: 1890 | E3: 1 | F3: March 1890 | G3: 1 | H3: 1 | I3: 1 | J3: 1 | K3: Banco Nacional, Italian Bank of the River Plate, Banco de la Provincia de BA, Banco Hipotecario Nacional | L3: Cachanosky (2012) Hodge (1970) | M3: Triner & Wandschneider (2005, p. 207) say that the panic was in March 1890 when bank runs occured. Cachanosky (2012) report multiple depositor runs and bank failures. Reinhart & Rogoff (2014) date the beginning of the panic to July 1890 (but they seem to have misread Triner & Wandschneider, 2005, which is their source). | N3: Della Paolera & Taylor (2001, pp. 37-64) report that in 1890 Argentina was heavily indebted and became unable to roll over existing debt, most of which was repayble in gold only. A severe sovereign debt crisis ensued. In the first quarter of 1890, the Banco de la Provincia and the Banco Nacional were hit by a run that finally triggered the crisis (Cachanosky, 2012). In 1891, the Italian Bank of the River Plate suffered severe runs and later failed. The River Plate Bank also suffered from a run, but received liquidity from Baron Rothschild (Hodge, 1970). Reinhart & Rogoff (2014) date the crisis to July 1890-1891,Della Paolera & Taylor (2001) say that the panic was in March 1891 (which might be a typo of the year). Triner & Wandschneider (2005, p. 207) date the panic to March 1890. Bordo and Eichengreen (1999) date the crisis the 1889-1890.
A4: Argentina | B4: 1914 | C4: 1 | D4: 1 | E4: 1 | F4: July 1914 | G4: 0 | H4: 1 | I4: 0 | J4: 1 | K4: Banco Frances failed in August 1914, but this seems to be the only outright failure. | L4: Lough (1915) | M4: The outbreak of the war in the end of July 1914 was accompanied by a dramatic flight to liquidty around the globe. Many Argentine banks faced severe pressures as international depositors demanded liquidity. "Total deposits at Argentine banks fell by nearly 20 percent. The brunt of the hardship fell on the private banks, which lost over 45 percent of their deposits." (Nakamura and Zarazaga, 2001, pp. 25-26). | N4: The crisis was precipitated by a land price boom which was fueled by heavy speculation and private indebtedness. Large amounts of credit were extended by European banks. Banco Frances failed in August 1914. (Lough, 1915). In 1912, depositors started to withdraw up to 20% of total deposits from banks in reponse to real economic disturbances (Nakamura and Zarazaga, 2001). Della Paolera and Taylor (2001) name this crisis "the worst recession in Argentine history" (p. 190).
A5: Argentina | B5: 1930 | C5: 1 | D5: 1931 | E5: 1 | F5: April 1931 | G5: 0 | H5: 1 | I5: 0 | J5: 1 | K5: There is no evidence of widespread bank failures | M5: Bernanke and James (1991), Bordo and Eichengreen (1999), Bordo et al. (2001), Reinhart and Rogoff (2009, 2014), and Conde (2010) all agree that this was a banking crisis, but we have no information either way whether that means there was a panic. However, we include it as a panic to be conservative (but more research needs to be done). Bernanke and James (1991) date the crisis to April 1931. | N5: Bernanke and James (1991), Bordo and Eichengreen (1999), Bordo et al. (2001), Reinhart and Rogoff (2009, 2014), and Conde (2010) all agree that this was a banking crisis. Argentina left the gold standard in 1929 but the debt overhang from the 1920s resulted in a build-up of insolvent bank loans. The collapse of commodity prices forced a generalized default of many farmers (Rocha & Solomou, 2015, appendix I). There is no narrative evidence of widespread bank failures (but detailed sources are hard to come by). Bernanke and James (1991) date the crisis to April 1931.
A6: Argentina | B6: 1934 | C6: 1 | D6: 1 | E6: 1 | F6: September 1934 | G6: 1 | H6: 1 | I6: 1 | J6: 1 | K6: Banco Espanol del Rio de la Plata, Banco el Hogar Argentina, Banco Argentina-Uruguayo, Ernesto Tornquist & Co. | L6: Bernanke & James (1991, p.53) | M6: Bernanke & James (1991) note that four banks were faced with a government-sponsored merger to resolve their problems. They date the panic to September 1934. Della Paolera & Taylor (2002) estimate that the government bailout included about 32 percent of the loans of the private banking system, suggesting that this was a systemic crisis. | N6: Della Paolera and Taylor (2002) write that the Argentine Great Depression was mild and short-lived by international standards (p. 190): Argentina established its central bank in 1935 to deal with the wave of financial distress in the private banking system. Bernanke and James (1991) date the crisis to September 1934. Bernanke and James (1991), Bordo et al. (2001), and Reinhart and Rogoff (2009) list this as a separate crisis from the 1931 event (Rocha & Solomou, 2015)
A7: Argentina | B7: 1980 | D7: 1 | E7: 1 | F7: March 1980 | G7: 1 | H7: 1 | I7: 1 | J7: 1 | K7: Banco de Intercambio Regional, Banco de los Andes, Banco Oddone, Banco International, and at least 64 more. | L7: Montanaro (1990) says that by 1982 86 financial institutions had failed. Caprio and Klingebiel (1996) state that more than 70 institutions were liquidated. | M7: Montanaro (1990) citing Feldman (1983) says that this financial crisis reached panic proportions in Argentina in March 1980. This is confirmed by Laeven & Valencia (2018). | N7: The crisis followed a wave of deregulation in the late 1970’s after a military government seized power in 1976. Other economic problems include high foreign debts and run-away inflation rates. Montanaro (1990) writes: "The financial crisis in Argentina exploded in March 1980 with the failure of the country’s main private bank, the Banco de Intercambio Regional. By the middle of 1982, 86 banks and financial institutions had failed, amongst which were the Banco de los Andes, the Banco Oddone and the Banco International, the third, seventh and ninth banks respectively in the country." The author cites Feldman (1983). Caprio and Klingebiel (1996) state that more than 70 institutions were liquidated. Reinhart & Rogoff (2009), citing Kaminsky and Reinhart (1996), say that failure of the large private bank Banco de Intercambio Regional led to runs on three other banks in March 1980. The month is confirmed by Laeven & Valencia (2018).
A8: Argentina | B8: 1985 | D8: 1 | E8: 1 | F8: May 1985 | G8: 1 | H8: 1 | I8: 1 | J8: 1 | K8: Banco de Italia y Rio de la Plata and at least 7 more. | L8: Chavez (1985) | M8: Hyperinflation caused major banking distress and a run on banks forcing the Argentine central bank to close several banks in May 1985 (Chavez, 1985). The panic month is confirmed by Kaminsky & Reinhart (1999). | N8: In the first half of the 1980s there was an inflation and public debt crisis that forced the government in 1985 to take drastic reform measures known as the "Plan Austral". In late 1983, Argentina received IMF loans but these were halted in March 1985 when Argentina was out of compliance with several economic targets (CIA, 1985). The resulting economic turbulence and hyperinflation caused major banking distress and a run on banks forcing the Argentine central bank to close several banks in May 1985. Subsequently, dollar deposits were frozen for 120 days (Chavez, 1985). Reinhart & Rogoff (2014) strangely no longer consider this a banking crisis in their 2014 update. Their original source was Kaminsky & Reinhart (1999), who date the crisis to 1989.
A9: Argentina | B9: 1989 | D9: 1 | E9: 1 | F9: April 1989 | G9: 1 | H9: 1 | I9: 1 | J9: 1 | K9: Failed banks held 40 percent of financial system assets. | L9: Caprio & Klingebiel (2003, p. 7) | M9: Laeven & Valencia (2018) say this was a banking crisis and date the panic to December 1989 when deposits were freezed (though it's probable that this date is too late, as bank runs likely occurred earlier. Kaminsky & Reinhart (1999) date the crisis to April 1989; however, it's not clear whether this date refers to panics, but we assume so to pick the earliest possible date to be conservative (though more research needs to be done). | N9: Stabilization policies caused a public debt crisis and hyperinflation that resulted in major bank distress (Beckerman, 1995). As a result, "nonperforming assets accounted for 27 percent of the aggregate portfolio and 37 percent of the portfolios of state banks. Failed banks held 40 percent of financial system assets" (Caprio & Klingebiel, 2003, p. 7). Laeven & Valencia (2018) also say that this is a banking crisis.
A10: Argentina | B10: 1995 | C10: 1 | D10: 1 | E10: 1 | F10: December 1994 | G10: 1 | H10: 1 | I10: 1 | J10: 1 | K10: At least 40 banks failed (almost one third of total banks). | L10: Jacome (2008, p. 27) Caprio & Klingebiel (2003, p. 7) | M10: "The end-1994 Mexican devaluation triggered a wave of uncertainty on the sustainability of the currency board in Argentina, leading to widespread deposit runs and large capital outflows. As a result, from end-December to January 1995, peso deposits fell more than 15 percent." (Jacome, 2008, p. 27). Laeven & Valencia (2018) date the beginning of the panic a little bit later to January 1995. | N10: Jacome (2008) continues: "From December 1994 to late 1996, about 40 small and medium-size banks failed or were acquired or merged (almost one third of total banks). To cope with the instability created by the “Tequila” shock, the Argentine government passed a law in May 1995 that allowed the central bank to get involved in the resolution of distressed banks" (p. 27). Caprio & Klingebiel (2003) say that "eight banks [were] suspended and three banks collapsed. Through the end of 1997, 63 of 205 banking institutions were closed or merged" (p. 7).
A11: Argentina | B11: 2000 | C11: 1 | D11: 2001 | E11: 1 | F11: March 2001 | G11: 1 | H11: 1 | I11: 1 | J11: 1 | K11: Bank resolutions were applied to three foreign banks that exited the market. (Need to find names of failed banks, likely many.) | L11: Jacome (2008, p. 42) | M11: "12 private and public banks (40% of deposits) received liquidity assistance" (Jacome et al., 2011, p. 27). Laeven & Valencia (2018) report this as a banking crisis with deposit freezes which indicates panic behavior. Caprio & Klingebiel (2003, p. 7) report that the first bank run occured in March 2001. | N11: Jacome et al. (2011): "In 2002 the value of the U.S. dollar quadrupled with respect to the peso as the country exited the currency board. Self-fulfilling expectations of a large currency depreciation turned into a speculative attack against the domestic currency and, hence, the central bank was forced to abandon the peg before international reserves were exhausted, thereby triggering a balance of payments crisis." Jacome (2008) report that "12 private and public banks (40% of deposits) received liquidity assistance, and bank resolution was applied to three foreign banks that exited the market." (p. 42). Laeven and Valencia (2018) date the crisis to November 2001 with deposit freezes starting in December 2001.
A12: Argentina | B12: 2008 | C12: 1 | E12: 0 | G12: 0 | H12: 0 | I12: 0 | J12: 0 | M12: Boonman, Jacobs, & Kuper (2011) acknowledge that in 2008 Latin American currencies depreciated sharply versus the US dollar but that this did not cause a banking crisis in Argentina. This is line with the general consensus in the literature that Latin American banks were largely spared from the Global Financial Crisis (e.g. Lane & Milesi-Ferretti, 2011).
A13: Argentina | B13: 2011 | C13: 1 | E13: 0 | G13: 0 | H13: 0 | I13: 0 | J13: 0 | M13: There is no evidence of a banking panic. | N13: There is no inidcation of any distress in the banking system during and around the year of 2011 in Argentina. The bank equity decline is probably related to the public debt restructuring process that started in 2005 and briefly raised concerns again in 2011 and 2012.
A14: Australia | B14: 1893 | C14: 1 | D14: 1 | E14: 1 | F14: April 1893 | G14: 1 | H14: 1 | I14: 1 | J14: 1 | K14: "Widespread failures were evident among the land banks and building societies through 1891 and 1892 and intensified the fears of trading bank depositors". "Thirteen of Australia’s twenty-two trading banks [had] suspended operations" and subsequently restructured. Mercantile Bank of Australia, Federal Bank of Australia, and Queensland National Bank failed. | L14: Merrett (2013, p. 410-412); Bordo & Eichengreen (1999, p. 40) | M14: Fisher & Kent (1999, p. 11) say that "the banking panic started in earnest with the suspension of payment by the Commercial Bank of Australia in April" of 1893. As a source they refer to Merrett (1989). | N14: Bordo & Eichengreen (1999) say that "this crisis reflected a domestic lending boom, as a result of which the quality of bank assets deteriorated significantly, and stringency on global credit markets reflecting the fallout from the Baring Crisis" (p. 40). Intermediaries became highly leveraged and commodity prices decreased which in turn lead to borrower defaults. This subsequently led to stress in the banking system. (Merrett, 2013).
A15: Australia | B15: 1931 | C15: 0 | D15: 1 | E15: 1 | F15: April 1931 | G15: 0 | H15: 1 | I15: 0 | J15: 1 | K15: The (small) Government Savings Bank of New South Wales failed. Fisher and Kent (1999) say that only three banks failed during the 1929-1931 depression, and two banks merged with other banks due to their perilious financial situation, but these were all small banks | L15: Sunday Herald (1953), 26 April, p. 10 and Polden (1972). | M15: Fitzgibbon and Gizycki (2001, pp. 39-40) say that a balance of payment crisis caused several banks to face deposit runs. | N15: Fitzgibbon and Gizycki (2001, pp. 39-40) say that "the depression was ushered in by the drying up of overseas loans to Australia and a sharp fall in export prices. Australia’s terms of trade fell dramatically, causing a balance of payments crisis in 1929." However, the depression was not as severe as the crisis of the 1890’s. Reinhart & Rogoff (2009, 2014) do not consider this a systemic banking crisis in their 2009 version but do so in their 2014 update.
A16: Australia | B16: 1952 | C16: 1 | E16: 0 | G16: 0 | H16: 0 | I16: 0 | J16: 0 | M16: Reinhart & Rogoff (2014) record a stock market collapse but no crisis. There is no evidence of a banking panic.
A17: Australia | B17: 1974 | C17: 1 | E17: 0 | G17: 0 | H17: 0 | I17: 0 | J17: 0 | M17: Reinhart & Rogoff (2014) record a stock market collapse but no crisis. There is no evidence of a panic among banks. | N17: There was a large boom in property lending by banks and, especially, by non-bank property lenders. After interest rates soared, and financial conditions deteriorated, property prices declined and many property lenders faced liquidity problems. Reinhart & Rogoff (2014) record a stock market collapse but not other crises. Although there was stress in the banking system there is no further indication in the literature for a banking crisis (in the strict sense of a "bank") in or around 1974.
A18: Australia | B18: 1989 | C18: 0 | D18: 1 | E18: 1 | F18: March 1990 | G18: 1 | H18: 1 | I18: 0 | J18: 1 | K18: State Bank of Victoria, State Bank of South Australia | L18: Fitzgibbon and Gizycki (2001, pp. 62-66) | M18: "The banking industry experienced its worst losses since the 1890s. [...] The State Bank of Victoria and the State Bank of South Australia suffered large losses, and state governments provided significant capital injections in the resolution of these problems. [..] There were runs [only] on numerous non-bank institutions [...]. Various banks began to suffer large depositor withdrawals, but the Reserve Bank made statements declaring its belief that the banks were generally safe and that it was willing to intervene to provide liquidity" and deposit guarantees, which effectively stopped the runs (Fitzgibbon and Gizycki, 2001, pp. 62-66). | N18: Fitzgibbon and Gizycki (2001, pp. 62-66) say that "In 1989, the combination of high interest rates and a softening in the commercial property market brought broadly based credit quality problems to light." Reinhart & Rogoff (2009, 2014) consider this a systemic banking crisis in their 2009 version but a non-systemic crisis in their 2014 update. Jordà, Schularick, & Taylor (2017) consider this a systemic banking crisis.
A19: Australia | B19: 2008 | C19: 1 | E19: 0 | G19: 0 | H19: 0 | I19: 0 | J19: 0 | M19: Except for Romer & Romer (2017) who report slightly elevated financial distress there is no evidence for a banking crisis in Australia during the Global Financial Crisis. This is in line with narrative accounts like Kennedy (2009).
A20: Austria | B20: 1873 | C20: 1 | D20: 1 | E20: 1 | F20: May 1873 | G20: 1 | H20: 1 | I20: 1 | J20: 1 | K20: "The number of banks and banking firms dropped from 141 in 1873 to 45 in 1878." Depening on the source, up to 100 banks failed or disappeared. | L20: Willis & Beckhart (1929, p. 108) For a comprehensive list of failed banks see Rieder (2017, ch. 1, Table 1.19) | M20: This is the well-known Gründerkrach banking crisis. Reinhart & Rogoff (2009) date it to May 1873. Rieder (2017, ch. 1) reports massive depositor withdrawals and bank runs.
A21: Austria | B21: 1888 | C21: 1 | E21: 0 | G21: 0 | H21: 0 | I21: 0 | J21: 0 | M21: There is no evidence of a banking panic.
A22: Austria | B22: 1920 | C22: 1 | E22: 0 | G22: 0 | H22: 0 | I22: 0 | J22: 0 | M22: There is no evidence of a banking panic.
A23: Austria | B23: 1924 | C23: 1 | D23: 1 | E23: 0 | G23: 1 | H23: 0 | I23: 1 | J23: 1 | K23: Allgemeine Depositenbank was liquidated in July 1924. Also, the Austro-Polnische Bank, the Austro-Orientbank, as well as the private Union Bank failed. Later, in 1927, Unionbank and Verkehrsbank failed and were merged with Creditanstalt. Biedermannbank failed in 1927. In 1924 the number of joint stock banks in Vienna dropped from 66 to 36. | L23: Bernanke & James (1991, p. 51) Kindleberger (1984) Macher (2018) (Schubert, 1992, p. 8) | M23: Allgemeine Depositenbank ran into difficulty in May 1924 due to speculation on the French franc, which caused it to go into liquidation after suffering heavy withdrawals. About 40,000 savers lost a part of their deposits. However, this seems to be the only run: all the other banks were either received deposit guarantees or were absorbed. in 1926, two important banks (Centralbank der deutschen Sparkassen and Postal Savings Bank) suffered heavy losses, but the government guaranteed deposits to avoid a panic. Other banks that suffered losses were mostly absorbed by Creditanstalt (Schubert, 1992, p. 8). | N23: Reinhart & Rogoff (2009, 2014) report this as a systemic banking crisis. The four major universal banks of Austria came under increasing distress (Macher, 2018). Following the end of the hyperinflation and stabilization of the currency, there was a stock market boom followed then by a stock market crash in 1924 that preceded the banking difficulties. (Schubert, 1992, p. 8).
A24: Austria | B24: 1931 | C24: 1 | D24: 1929, 1931 | E24: 1 | F24: May 1931 | G24: 1 | H24: 1 | I24: 1 | J24: 1 | K24: Bodencreditanstalt, the second largest bank, fails in 1929 and is merged with Creditanstalt. The largest bank Creditanstalt failed on May 11, 1931. | L24: Bernanke & James (1991, p. 51) Macher (2018) | M24: Macher (2018) report large-scale deposit withdrawal and financial stress in 1931. The failure of Creditanstalt in May 1931 usheres in a full-blown banking panic. | N24: Reinhart & Rogoff (2009, 2014) report 1929 and 1931 as systemic banking crises. Bodencreditanstalt encountered serious liquidity problems in October 1929, but this is not considered a panic because: the bank could "meet these demands by taking (excessive) recourse to the discount window of the Austrian National Bank", and eventually the government arranged a merger with a strong partner, Creditanstalt (Schubert, 1992, p. 8).
A25: Austria | B25: 1966 | C25: 1 | E25: 0 | G25: 0 | H25: 0 | I25: 0 | J25: 0 | M25: There is no evidence of a banking panic.
A26: Austria | B26: 1982 | C26: 1 | E26: 0 | G26: 0 | H26: 0 | I26: 0 | J26: 0 | M26: There is no evidence of a banking panic. Lo Duca et al. (2017) confirm that there was only a limited effect on the Austrian banking system due to an external shock from global monetary policy.
A27: Austria | B27: 1995 | C27: 1 | E27: 0 | G27: 0 | H27: 0 | I27: 0 | J27: 0 | M27: There is no evidence of a banking panic.
A28: Austria | B28: 2008 | C28: 1 | D28: 1 | E28: 1 | F28: September 2008 | G28: 1 | H28: 1 | I28: 1 | J28: 1 | K28: Kommunalkredit Austria was nationalized in 2008. Constantia Privatbank failed in 2008 and was rescued by private banks. Hypo Alpe Adria was nationalized in 2009 and later liquidated. Volksbank receives capital support from the government in 2009 and is later liquidated. | L28: Lo Duca et al. (2017) Die Presse (2008) Die Presse (2009) Atkins (2016) | M28: Laeven & Valencia (2018), Reinhart & Rogoff (2014), and Romer & Romer (2017) agree that this was a systemic banking crisis. As with many European economies, Laeven & Valencia (2018) date the beginning of the panic to September 2008 when Lehman Brothers collapsed.
A29: Austria | B29: 2011 | C29: 1 | E29: 0 | G29: 1 | H29: 0 | I29: 1 | J29: 1 | K29: Volksbank again suffered large losses in 2011, was part-nationalized in 2011 by means of a debt-equity conversion of 250M EUR, and in October 2014, expecting failure of the ECB/EBA stress tests, was split up and restructed. A second bank, Hypo Alpe Adria, was part-nationalized due to European sovereign debt losses and split into a "good bank" and "bad bank" in 2014. Pfandbriefbank Oesterreich had to be rescued in 2015 by its regional bank owners. | M29: Reinhart & Rogoff (2014) report all years from 2008 through 2011 as a systemic bank crisis. Volksbank suffered losses from Greek debt defaults and other sources (Copolla, 2015). Romer & Romer (2017) report elevated stress in the banking system starting in the second half of 2011.
A30: Belgium | B30: 1870 | C30: 0 | D30: 1 | E30: 1 | F30: July 1870 | G30: 0 | H30: 1 | I30: 0 | J30: 1 | K30: There is no evidence of widespread bank failures. | M30: The evacuation of gold reserves from the capital sparked a panic in July 1870 and people demanded their notes to be exchanged for coins (Buyst & Maes, 2007, p. 17). Also, Reinhart & Rogoff (2007, 2014) date the beginning of this systemic banking crisis to July 1870.
A31: Belgium | B31: 1876 | C31: 1 | E31: 1 | F31: March 1876 | G31: 1 | H31: 1 | I31: 1 | J31: 1 | K31: Major bank Banque de Belgique failed in 1876 and was finally liquidated later in 1885. Banque de Bruxelles and Banque Central Anversoise had to be re-organized. | L31: Cameron & Bovykin (1991, p. 121) Buyst & Maes (2007, p. 24) Grossman (2010, p. 299) | M31: Buyst & Maes (2007, p. 22, 24) consider this a major banking crisis and date its beginning to March 1876 when Banque de Belgique failed. No direct evidence of a panic, but likely, so we mark it to be conservative.
A32: Belgium | B32: 1883 | C32: 0 | D32: 1885 | E32: 1 | F32: Could not be dated | G32: 1 | H32: 1 | I32: 0 | J32: 1 | K32: Third-largest bank Banque des Travaux Publics failed in 1885. Other smaller banks seemed to have failed, as well. | L32: Buyst & Maes (2008b, p. 169-170) | M32: Buyst & Maes (2008b, p. 169-170) record 1885-1886 as a separate banking panic with several bank failures. No direct evidence of a panic, but likely, so we mark it to be conservative.
A33: Belgium | B33: 1914 | D33: 1 | E33: 1 | F33: July 1914 | G33: 1 | H33: 1 | I33: 1 | J33: 1 | K33: Banque de Reports, de Fonds Publiques et de Dépôts d’Anvers were rescued and acquired by Société Générale. | L33: Buyst & Maes (2008b, p. 169-171) | M33: Reinhart & Rogoff (2009, 2014) date this systemic banking crisis to July 1914 when the war broke out. Panic withdrawals and suspension of bank note convertibility (Grossman, 2010, p. 300).
A34: Belgium | B34: 1925 | C34: 0 | D34: 1 | E34: 0 | G34: 0 | H34: 0 | I34: 0 | J34: 0 | K34: There is no evidence of widespread bank failures. | M34: Reinhart & Rogoff (2009, 2014) consider this a systemic banking crisis. After a close reading of their sources, however, no evidence for widespread distress or panic could be found. The authors cite Johnson (1997) who in turn refer to a "funding crisis" in Makinen and Woodward (1990). But "funding crisis" refers to, in the original article, the inability of governments and nonfinancial firms to rollover their debt, not a banking funding crisis.
A35: Belgium | B35: 1929 | C35: 1 | D35: 1931, 1934 | E35: 1 | F35: May 1931 | G35: 1 | H35: 1 | I35: 1 | J35: 1 | K35: Mid-sized Banque Chaudoir failed in 1930. Banque Belge de Travail and Algemeene Bankvereeniging failed in 1934. | L35: Buyst & Maes (2008a) Bernanke & James (1991, p. 52 | M35: Rumors about imminent failure of Banque de Bruxelles (second largest bank) induced withdrawals from all banks, especially from foreign depositors (Bernanke & James, 1991, p. 52). Reinhart & Rogoff (2009) follow Bernanke & James (1991) and date the beginning of the panic to May 1931.
A36: Belgium | B36: 1939 | D36: 1 | E36: 1 | F36: December 1939 | G36: 1 | H36: 1 | I36: 1 | J36: 1 | K36: Credit Anversois | L36: Buyst & Maes (2008a, p. 19) | M36: Large capital outflows in December 1939 from Belgian banks resulted in a banking crisis (Reinhart & Rogoff, 2009, 2014).
A37: Belgium | B37: 1974 | C37: 1 | E37: 0 | G37: 0 | H37: 0 | I37: 0 | J37: 0 | M37: There is no evidence of a banking panic.
A38: Belgium | B38: 1980 | C38: 1 | E38: 0 | G38: 0 | H38: 0 | I38: 0 | J38: 0 | K38: Three small banks (Banque Copine, Banque Andes and Geoffrey's Bank) failed but there is no further evidence of widespread bank failures. | L38: Gup (1998, Table 4.1) | M38: There is no evidence of a banking panic.
A39: Belgium | B39: 2002 | C39: 1 | E39: 0 | G39: 0 | H39: 0 | I39: 0 | J39: 0 | M39: There is no evidence of a banking panic.
A40: Belgium | B40: 2008 | C40: 1 | D40: 1 | E40: 1 | F40: September 2008 | G40: 1 | H40: 1 | I40: 1 | J40: 1 | K40: Fortis, then the largest financial-services firm, was nationalized. Dexia was rescued by several governments and later liquidated. | L40: van der Starre & Louis (2008) BBC News (2008) | M40: Laeven & Valencia (2018), Reinhart & Rogoff (2014), and Romer & Romer (2017) agree that this was a systemic banking crisis. As with many European economies, Laeven & Valencia (2018) date the beginning of the panic to September 2008 when Lehman Brothers collapsed.
...
